Workbook
Name Aluschale: Tabelle2!$O$4:$O$13
Name Aluschalen: Tabelle2!$O$4:$O$13
Name Fenster: Tabelle2!$L$3:$L$13
Name Fensterart: Tabelle2!$L$3:$L$9
Name Fenstertyp: [1]Tabelle2!$L$3:$L$9
Name Holzart: [1]Tabelle2!$G$3:$G$5
Name OF: [1]Tabelle2!$E$3:$E$4
Name zubehör: Tabelle2!$I$3:$I$15
Name Zubehör_beschreibung: [1]Tabelle2!$I$3:$I$14
Name zubehörteile: Tabelle2!$I$3:$I$19

Sheet Tabelle1
A2: Kunde: | I2: Pos | J2: Stk | K2: breite | L2: Höhe | M2: Beschreibung | O2: Fläche m² | Q2: Lfm montage | S2: Kompriband | U2: APUleiste | W2: Fensterbleche
A3: Objektnummer:
A4: Art der Arbeit: | O4: =(K4*L4)*J4 -> 0 | Q4: =((K4+L4)*2)*J4 -> 0 | S4: =(L4*2)+K4 -> 0 | U4: =((L4*4)+K4)*J4 -> 0 | W4: =K4*J4 -> 0
A5: Sachbearbeiter | O5: =(K5*L5)*J5 -> 0 | Q5: =((K5+L5)*2)*J5 -> 0 | S5: =(L5*2)+K5 -> 0 | U5: =((L5*4)+K5)*J5 -> 0 | W5: =K5*J5 -> 0
O6: =(K6*L6)*J6 -> 0 | Q6: =((K6+L6)*2)*J6 -> 0 | S6: =(L6*2)+K6 -> 0 | U6: =((L6*4)+K6)*J6 -> 0 | W6: =K6*J6 -> 0
O7: =(K7*L7)*J7 -> 0 | Q7: =((K7+L7)*2)*J7 -> 0 | S7: =(L7*2)+K7 -> 0 | U7: =((L7*4)+K7)*J7 -> 0 | W7: =K7*J7 -> 0
O8: =(K8*L8)*J8 -> 0 | Q8: =((K8+L8)*2)*J8 -> 0 | S8: =(L8*2)+K8 -> 0 | U8: =((L8*4)+K8)*J8 -> 0 | W8: =K8*J8 -> 0
O9: =(K9*L9)*J9 -> 0 | Q9: =((K9+L9)*2)*J9 -> 0 | S9: =(L9*2)+K9 -> 0 | U9: =((L9*4)+K9)*J9 -> 0 | W9: =K9*J9 -> 0
O10: =(K10*L10)*J10 -> 0 | Q10: =((K10+L10)*2)*J10 -> 0 | S10: =(L10*2)+K10 -> 0 | U10: =((L10*4)+K10)*J10 -> 0 | W10: =K10*J10 -> 0
O11: =(K11*L11)*J11 -> 0 | Q11: =((K11+L11)*2)*J11 -> 0 | S11: =(L11*2)+K11 -> 0 | U11: =((L11*4)+K11)*J11 -> 0 | W11: =K11*J11 -> 0 | X11: 0 | Y11: LF Montage Hebeschiebetüren
O12: =(K12*L12)*J12 -> 0 | Q12: =((K12+L12)*2)*J12 -> 0 | S12: =(L12*2)+K12 -> 0 | U12: =((L12*4)+K12)*J12 -> 0 | W12: =K12*J12 -> 0
O13: =(K13*L13)*J13 -> 0 | Q13: =((K13+L13)*2)*J13 -> 0 | S13: =(L13*2)+K13 -> 0 | U13: =((L13*4)+K13)*J13 -> 0 | W13: =K13*J13 -> 0 | X13: =Q35-X11 -> 0 | Y13: LF montage Fenster
O14: =(K14*L14)*J14 -> 0 | Q14: =((K14+L14)*2)*J14 -> 0 | S14: =(L14*2)+K14 -> 0 | U14: =((L14*4)+K14)*J14 -> 0 | W14: =K14*J14 -> 0
O15: =(K15*L15)*J15 -> 0 | Q15: =((K15+L15)*2)*J15 -> 0 | S15: =(L15*2)+K15 -> 0 | U15: =((L15*4)+K15)*J15 -> 0 | W15: =K15*J15 -> 0
O16: =(K16*L16)*J16 -> 0 | Q16: =((K16+L16)*2)*J16 -> 0 | S16: =(L16*2)+K16 -> 0 | U16: =((L16*4)+K16)*J16 -> 0 | W16: =K16*J16 -> 0
O17: =(K17*L17)*J17 -> 0 | Q17: =((K17+L17)*2)*J17 -> 0 | S17: =(L17*2)+K17 -> 0 | U17: =((L17*4)+K17)*J17 -> 0 | W17: =K17*J17 -> 0
O18: =(K18*L18)*J18 -> 0 | Q18: =((K18+L18)*2)*J18 -> 0 | S18: =(L18*2)+K18 -> 0 | U18: =((L18*4)+K18)*J18 -> 0 | W18: =K18*J18 -> 0
O19: =(K19*L19)*J19 -> 0 | Q19: =((K19+L19)*2)*J19 -> 0 | S19: =(L19*2)+K19 -> 0 | U19: =((L19*4)+K19)*J19 -> 0 | W19: =K19*J19 -> 0
O20: =(K20*L20)*J20 -> 0 | Q20: =((K20+L20)*2)*J20 -> 0 | S20: =(L20*2)+K20 -> 0 | U20: =((L20*4)+K20)*J20 -> 0 | W20: =K20*J20 -> 0
O21: =(K21*L21)*J21 -> 0 | Q21: =((K21+L21)*2)*J21 -> 0 | S21: =(L21*2)+K21 -> 0 | U21: =((L21*4)+K21)*J21 -> 0 | W21: =K21*J21 -> 0
O22: =(K22*L22)*J22 -> 0 | Q22: =((K22+L22)*2)*J22 -> 0 | S22: =(L22*2)+K22 -> 0 | U22: =((L22*4)+K22)*J22 -> 0 | W22: =K22*J22 -> 0
O23: =(K23*L23)*J23 -> 0 | Q23: =((K23+L23)*2)*J23 -> 0 | S23: =(L23*2)+K23 -> 0 | U23: =((L23*4)+K23)*J23 -> 0 | W23: =K23*J23 -> 0
O24: =(K24*L24)*J24 -> 0 | Q24: =((K24+L24)*2)*J24 -> 0 | S24: =(L24*2)+K24 -> 0 | U24: =((L24*4)+K24)*J24 -> 0 | W24: =K24*J24 -> 0
O25: =(K25*L25)*J25 -> 0 | Q25: =((K25+L25)*2)*J25 -> 0 | S25: =(L25*2)+K25 -> 0 | U25: =((L25*4)+K25)*J25 -> 0 | W25: =K25*J25 -> 0
... O29: =(K29*L29)*J29 -> 0 | Q29: =((K29+L29)*2)*J29 -> 0 | S29: =(L29*2)+K29 -> 0 | U29: =((L29*4)+K29)*J29 -> 0 | W29: =K29*J29 -> 0
Q30: =((K30+L30)*2)*J30 -> 0 | S30: =(L30*2)+K30 -> 0 | U30: =((L30*4)+K30)*J30 -> 0 | W30: =K30*J30 -> 0
Q31: =((K31+L31)*2)*J31 -> 0 | S31: =(L31*2)+K31 -> 0 | U31: =((L31*4)+K31)*J31 -> 0 | W31: =K31*J31 -> 0
O32: =SUM(O3:O31) -> 0 | Q32: =((K32+L32)*2)*J32 -> 0 | S32: =(L32*2)+K32 -> 0 | U32: =((L32*4)+K32)*J32 -> 0 | W32: =K32*J32 -> 0
Q33: =((K33+L33)*2)*J33 -> 0 | S33: =(L33*2)+K33 -> 0 | U33: =((L33*4)+K33)*J33 -> 0 | W33: =K33*J33 -> 0
Q34: =((K34+L34)*2)*J34 -> 0 | S34: =(L34*2)+K34 -> 0 | U34: =((L34*4)+K34)*J34 -> 0 | W34: =K34*J34 -> 0
A35: Fenstertyp | Q35: =SUM(Q3:Q30) -> 0 | S35: =SUM(S4:S34) -> 0 | U35: =SUM(U4:U24) -> 0 | W35: =SUM(W4:W24) -> 0
A36: Green Evolution
A37: Glaspreis | B37: 56
A38: Fglaspreis absturzsichernd | B38: 0
A39: montage Fenster | B39: 35 | C39: =B39*Q35 -> 0 | Q39: €/LFM
A40: Demontage fenster | B40: 0 | C40: =B40*Q35 -> 0 | M40: Verbreiterung 20mm | Q40: 21
A41: montage dämmung | B41: 0 | C41: =B41*W35 -> 0 | M41: Einstandsprofil 100mm | Q41: 45
A42: montage panzer | B42: 65 | C42: =B42*M104 -> 0 | M42: Verbreiterung 200 | Q42: 81
A43: montage bleche | B43: 15 | C43: =B43*W35 -> 0 | M43: Breiter Stock | N43: 2x | Q43: 18
A44: montage Haustüre | B44: 60 | C44: =((D63*2*(+(E63*2)))/1000000)*B44 -> 0
...

Sheet Tabelle3
O10: Aufschläge 5 und 15%
B11: =Tabelle1!A49 -> Pos: | C11: =Tabelle1!B49 -> Beschreibung | D11: =Tabelle1!C49 -> Stk | E11: =Tabelle1!D49 -> Breite | F11: =Tabelle1!E49 -> Höhe | G11: ohne Rabatt | H11: Ges ohne Rabatt | I11: =Tabelle1!Y49 -> Selbstkosten einzeln: | J11: Lfm pro position | K11: =Tabelle1!Z49 -> Selbstkosten Gesamt | L11: =Tabelle1!#REF! -> #REF! | M11: =Tabelle1!#REF! -> #REF! | N11: VK einzel | O11: VK gesamt
B13: =Tabelle1!A51 -> 0 | C13: =Tabelle1!B51 -> 0 | D13: =Tabelle1!C51 -> 0 | E13: =Tabelle1!D51 -> 0 | F13: =Tabelle1!E51 -> 0 | G13: =Tabelle1!S51 -> 0 | H13: =Tabelle1!T51 -> 0 | I13: =Tabelle1!Y51 -> 0 | J13: =Tabelle1!#REF! -> #REF! | K13: =Tabelle1!#REF! -> #REF! | L13: =Tabelle1!#REF! -> #REF! | M13: =Tabelle1!#REF! -> #REF! | N13: =Tabelle1!AC51 -> 0 | O13: =Tabelle1!AD51 -> #REF!
B14: =Tabelle1!A52 -> 0 | C14: =Tabelle1!B52 -> 0 | D14: =Tabelle1!C52 -> 0 | E14: =Tabelle1!D52 -> 0 | F14: =Tabelle1!E52 -> 0 | G14: =Tabelle1!S52 -> 0 | H14: =Tabelle1!T52 -> 0 | I14: =Tabelle1!Y52 -> 0 | J14: =Tabelle1!#REF! -> #REF! | K14: =Tabelle1!Z51 -> 0 | L14: =Tabelle1!#REF! -> #REF! | M14: =Tabelle1!#REF! -> #REF! | N14: =Tabelle1!AC52 -> 0 | O14: =Tabelle1!AD52 -> #REF!
B15: =Tabelle1!A53 -> 0 | C15: =Tabelle1!B53 -> 0 | D15: =Tabelle1!C53 -> 0 | E15: =Tabelle1!D53 -> 0 | F15: =Tabelle1!E53 -> 0 | G15: =Tabelle1!S53 -> 0 | H15: =Tabelle1!T53 -> 0 | I15: =Tabelle1!Y53 -> 0 | J15: =Tabelle1!#REF! -> #REF! | K15: =Tabelle1!Z53 -> 0 | L15: =Tabelle1!#REF! -> #REF! | M15: =Tabelle1!#REF! -> #REF! | N15: =Tabelle1!AC53 -> 0 | O15: =Tabelle1!AD53 -> #REF!
B16: =Tabelle1!A54 -> 0 | C16: =Tabelle1!B54 -> 0 | D16: =Tabelle1!C54 -> 0 | E16: =Tabelle1!D54 -> 0 | F16: =Tabelle1!E54 -> 0 | I16: =Tabelle1!Y54 -> 0 | J16: =Tabelle1!#REF! -> #REF! | K16: =Tabelle1!Z54 -> 0 | L16: =Tabelle1!#REF! -> #REF! | M16: =Tabelle1!#REF! -> #REF! | N16: =Tabelle1!AC54 -> 0 | O16: =Tabelle1!AD54 -> #REF!
B17: =Tabelle1!A55 -> 0 | C17: =Tabelle1!B55 -> 0 | D17: =Tabelle1!C55 -> 0 | E17: =Tabelle1!D55 -> 0 | F17: =Tabelle1!E55 -> 0 | G17: =Tabelle1!S55 -> 0 | H17: =Tabelle1!T55 -> 0 | I17: =Tabelle1!Y55 -> 0 | J17: =Tabelle1!#REF! -> #REF! | K17: =Tabelle1!Z55 -> 0 | L17: =Tabelle1!#REF! -> #REF! | M17: =Tabelle1!#REF! -> #REF! | N17: =Tabelle1!AC55 -> 0 | O17: =Tabelle1!AD55 -> #REF!
B18: =Tabelle1!A56 -> 0 | C18: =Tabelle1!B56 -> 0 | D18: =Tabelle1!C56 -> 0 | E18: =Tabelle1!D56 -> 0 | F18: =Tabelle1!E56 -> 0 | G18: =Tabelle1!S56 -> 0 | H18: =Tabelle1!T56 -> 0 | I18: =Tabelle1!Y56 -> 0 | J18: =Tabelle1!#REF! -> #REF! | K18: =Tabelle1!Z56 -> 0 | L18: =Tabelle1!#REF! -> #REF! | M18: =Tabelle1!#REF! -> #REF! | N18: =Tabelle1!AC56 -> 0 | O18: =Tabelle1!AD56 -> #REF!
B19: =Tabelle1!A57 -> 0 | C19: =Tabelle1!B57 -> 0 | D19: =Tabelle1!C57 -> 0 | E19: =Tabelle1!D57 -> 0 | F19: =Tabelle1!E57 -> 0 | G19: =Tabelle1!S57 -> 0 | H19: =Tabelle1!T57 -> 0 | I19: =Tabelle1!Y57 -> 0 | J19: =Tabelle1!#REF! -> #REF! | K19: =Tabelle1!Z57 -> 0 | L19: =Tabelle1!#REF! -> #REF! | M19: =Tabelle1!#REF! -> #REF! | N19: =Tabelle1!AC57 -> 0 | O19: =Tabelle1!AD57 -> #REF!
B20: =Tabelle1!A58 -> 0 | C20: =Tabelle1!B58 -> 0 | D20: =Tabelle1!C58 -> 0 | E20: =Tabelle1!D58 -> 0 | F20: =Tabelle1!E58 -> 0 | I20: =Tabelle1!Y58 -> 0 | J20: =Tabelle1!#REF! -> #REF! | K20: =Tabelle1!Z58 -> 0 | L20: =Tabelle1!#REF! -> #REF! | M20: =Tabelle1!#REF! -> #REF! | N20: =Tabelle1!AC58 -> 0 | O20: =Tabelle1!AD58 -> #REF!
B21: =Tabelle1!A59 -> 0 | C21: =Tabelle1!B59 -> 0 | D21: =Tabelle1!C59 -> 0 | E21: =Tabelle1!D59 -> 0 | F21: =Tabelle1!E59 -> 0 | I21: =Tabelle1!Y59 -> 0 | J21: =Tabelle1!#REF! -> #REF! | K21: =Tabelle1!Z59 -> 0 | L21: =Tabelle1!#REF! -> #REF! | M21: =Tabelle1!#REF! -> #REF! | N21: =Tabelle1!AC59 -> 0 | O21: =Tabelle1!AD59 -> #REF!
B22: =Tabelle1!A60 -> 0 | C22: =Tabelle1!B60 -> 0 | D22: =Tabelle1!C60 -> 0 | E22: =Tabelle1!D60 -> 0 | F22: =Tabelle1!E60 -> 0 | G22: =Tabelle1!S60 -> 0 | H22: =Tabelle1!T60 -> 0 | I22: =Tabelle1!Y60 -> 0 | J22: =Tabelle1!#REF! -> #REF! | K22: =Tabelle1!Z60 -> 0 | L22: =Tabelle1!#REF! -> #REF! | M22: =Tabelle1!#REF! -> #REF! | N22: =Tabelle1!AC60 -> 0 | O22: =Tabelle1!AD60 -> #REF!
B23: =Tabelle1!A61 -> 0 | C23: =Tabelle1!B61 -> 0 | D23: =Tabelle1!C61 -> 0 | E23: =Tabelle1!D61 -> 0 | F23: =Tabelle1!E61 -> 0 | I23: =Tabelle1!Y61 -> 0 | J23: =Tabelle1!#REF! -> #REF! | K23: =Tabelle1!Z61 -> 0 | L23: =Tabelle1!#REF! -> #REF! | M23: =Tabelle1!#REF! -> #REF! | N23: =Tabelle1!AC61 -> 0 | O23: =Tabelle1!AD61 -> #REF!
B24: =Tabelle1!A62 -> 0 | C24: =Tabelle1!B62 -> 0 | D24: =Tabelle1!C62 -> 0 | E24: =Tabelle1!D62 -> 0 | F24: =Tabelle1!E62 -> 0 | G24: =Tabelle1!S62 -> 0 | H24: =Tabelle1!T62 -> 0 | I24: =Tabelle1!Y62 -> 0 | J24: =Tabelle1!#REF! -> #REF! | K24: =Tabelle1!Z62 -> 0 | L24: =Tabelle1!#REF! -> #REF! | M24: =Tabelle1!#REF! -> #REF! | N24: =Tabelle1!AC62 -> 0 | O24: =Tabelle1!AD62 -> #REF!
B25: =Tabelle1!A63 -> 0 | C25: =Tabelle1!B63 -> 0 | D25: =Tabelle1!C63 -> 0 | E25: =Tabelle1!D63 -> 0 | F25: =Tabelle1!E63 -> 0 | G25: =Tabelle1!S63 -> 0 | H25: =Tabelle1!T63 -> 0 | I25: =Tabelle1!Y63 -> 0 | J25: =Tabelle1!#REF! -> #REF! | K25: =Tabelle1!Z63 -> 0 | L25: =Tabelle1!#REF! -> #REF! | M25: =Tabelle1!#REF! -> #REF! | N25: =Tabelle1!AC63 -> 0 | O25: =Tabelle1!AD63 -> #REF!
B26: =Tabelle1!A64 -> 0 | C26: =Tabelle1!B64 -> 0 | D26: =Tabelle1!C64 -> 0 | E26: =Tabelle1!D64 -> 0 | F26: =Tabelle1!E64 -> 0 | I26: =Tabelle1!Y64 -> 0 | J26: =Tabelle1!#REF! -> #REF! | K26: =Tabelle1!Z64 -> 0 | M26: =Tabelle1!#REF! -> #REF! | N26: =Tabelle1!AC64 -> 0 | O26: =Tabelle1!AD64 -> #REF!
M28: =SUM(M13:M26) -> #REF! | O28: =SUM(O13:O26) -> #REF!

Sheet Tabelle2
E3: OF Holz | G3: Fichte | I3: Schienen | L3: Green Evolution
E4: OF Holz-Alu | G4: Lärche | I4: RC2 beschläge | L4: Blue Evolution | O4: 86
G5: Eiche | I5: Leer | L5: Klima Futur
I6: Voll verdeckte beschläge | L6: Garda D | O6: 54.14
I7: Verbreiterungen | L7: Garda 82 | O7: 66
I8: Sonder | L8: Garda HF | O8: 74
I9: Aluschale sonder | L9: Sonder | O9: 96.14
I10: Beschläge sonder | O10: 86.14
I11: Sonderglas | O11: 100.14
I12: Sonder griffe
I13: ApuleistenSprossen
I14: Aufpreis schräg Element
I15: Sprossen
I16: Flügelheber
I17: Einstandsprofil
I18: Fliegengitter
I19: Mehrpreis Eiche
I20: Eckpfosten
I21: Verbreiterung
